<robot name="naro">

    <material name="blue">
        <color rgba="0 0 0.8 1"/>
    </material>
    <material name="red">
        <color rgba="0.8 0 0 1"/>
    </material>
    <material name="green">
        <color rgba="0 0.8 0 1"/>
    </material>
    <material name="purple">
        <color rgba="0.8 0 0.8 1"/>
    </material>

    <gazebo>
        <plugin name="gazebo_ros_control" filename="libgazebo_ros_control.so">
        </plugin>
    </gazebo>

	<!-- * * * Link Definitions * * * -->
    <link name="base_link">
 	    <inertial>
            <origin xyz="0 0 0" rpy="0 0 0"/>
            <mass value="1.40919" />
            <inertia ixx="0.0005726" ixy="0.0" ixz="0.0" iyy="0.0005726" iyz="0.0" izz="0.0002704"/>
        </inertial>
        <collision>
            <origin rpy="0.0 0 0" xyz="0 0 0"/>
            <geometry>
                <cylinder radius="0.052" length="0.162"/>
            </geometry>
        </collision>
        <visual>
            <origin rpy="0.0 0 0" xyz="0 0 0"/>
            <geometry>
                <cylinder radius="0.052" length="0.162"/>
            </geometry>
            <material name="red"/>
        </visual>
	</link>

    <gazebo reference="base_link">
        <kp>1000000.0</kp>
        <kd>1000000.0</kd>
        <mu1>10.0</mu1>
        <mu2>10.0</mu2>
        <material>Gazebo/Red</material>
    </gazebo>

    <link name="NaroBody_2_link">
 	    <inertial>
            <origin xyz="0 0 0.0362" rpy="0 0 0"/>
            <mass value="0.6199" />
            <inertia ixx="0.000220439071667" ixy="0.0" ixz="0.0" iyy="0.000220439071667" iyz="0.0" izz="0.00026615281"/>
        </inertial>
        <collision>
            <origin xyz="0 0 0.0362" rpy="0 0 0"/>
            <geometry>
                <cylinder radius="0.05159" length="0.0724"/>
            </geometry>
        </collision>
        <visual>
            <origin xyz="0 0 0.0362" rpy="0 0 0"/>
            <geometry>
                <cylinder radius="0.05159" length="0.0724"/>
            </geometry>
            <material name="blue"/>
        </visual>


	</link>
    <!-- This is for color and physical properties in Gazebo, color won't work with the material tag in gazebo
    only for URDF coloring -->
    <gazebo reference="NaroBody_2_link">
        <kp>1000000.0</kp>
        <kd>1000000.0</kd>
        <mu1>10.0</mu1>
        <mu2>10.0</mu2>
        <material>Gazebo/Blue</material>



    </gazebo>

    <joint name="NaroBody_1_NaroBody_2_joint" type="revolute">
    	<parent link="base_link"/>
    	<child link="NaroBody_2_link"/>
        <origin xyz="0 0 0.096" rpy="0 0 0"/>
        <limit lower="-0.2" upper="0.2" effort="10.0" velocity="1.0"/>
        <axis xyz="1 0 0"/>
	</joint>
	
    <transmission name="tran1">
        <type>transmission_interface/SimpleTransmission</type>
        <joint name="NaroBody_1_NaroBody_2_joint">
            <hardwareInterface>EffortJointInterface</hardwareInterface>
        </joint>
        <actuator name="motor1">
            <hardwareInterface>EffortJointInterface</hardwareInterface>
            <mechanicalReduction>1</mechanicalReduction>
        </actuator>
    </transmission>

    <link name="NaroBody_3_link">
 	    <inertial>
            <origin xyz="0 0 0.0267885" rpy="0 0 0"/>
            <mass value="0.141" />
            <inertia ixx="8.87413829167e-05" ixy="0.0" ixz="0.0" iyy="8.87413829167e-05" iyz="0.0" izz="8.18246025e-05"/>
        </inertial>
        <collision>
            <origin xyz="0 0 0.0267885" rpy="0 0 0"/>
            <geometry>
                <cylinder radius="0.028605" length="0.05357"/>
            </geometry>
        </collision>
        <visual>
            <origin xyz="0 0 0.0267885" rpy="0 0 0"/>
            <geometry>
                <cylinder radius="0.028605" length="0.05357"/>
            </geometry>
            <material name="green"/>
        </visual>
	</link>
    <!-- This is for color and physical properties in Gazebo, color won't work with the material tag in gazebo
    only for URDF coloring -->
    <gazebo reference="NaroBody_3_link">
        <kp>1000000.0</kp>
        <kd>1000000.0</kd>
        <mu1>10.0</mu1>
        <mu2>10.0</mu2>
        <material>Gazebo/Green</material>



    </gazebo>

    <joint name="NaroBody_2_NaroBody_3_joint" type="revolute">
    	<parent link="NaroBody_2_link"/>
    	<child link="NaroBody_3_link"/>
        <origin xyz="0 0 0.0874" rpy="0 0 0"/>
        <limit lower="-0.2" upper="0.2" effort="5.0" velocity="1.0"/>
        <axis xyz="1 0 0"/>
	</joint>
	
    <transmission name="tran2">
        <type>transmission_interface/SimpleTransmission</type>
        <joint name="NaroBody_2_NaroBody_3_joint">
            <hardwareInterface>EffortJointInterface</hardwareInterface>
        </joint>
        <actuator name="motor2">
            <hardwareInterface>EffortJointInterface</hardwareInterface>
            <mechanicalReduction>1</mechanicalReduction>
        </actuator>
    </transmission>
    
    
    <link name="Naro_caudal_fin_link">
 	    <inertial>
            <origin xyz="0 0.07 0" rpy="0 0 0"/>
            <mass value="0.0945" />
            <inertia ixx="0.000220439071667" ixy="0.0" ixz="0.0" iyy="0.000220439071667" iyz="0.0" izz="0.00026615281"/>
        </inertial>
        <collision>
            <origin xyz="0 0.07 0" rpy="0 0 0"/>
            <geometry>
                <cylinder radius="0.07" length="0.006"/>
            </geometry>
        </collision>
        <visual>
            <origin xyz="0 0.07 0" rpy="0 0 0"/>
            <geometry>
                <cylinder radius="0.07" length="0.006"/>
            </geometry>
            <material name="purple"/>
        </visual>
	</link>
    <!-- This is for color and physical properties in Gazebo, color won't work with the material tag in gazebo
    only for URDF coloring -->
    <gazebo reference="Naro_caudal_fin_link">
        <kp>1000000.0</kp>
        <kd>1000000.0</kd>
        <mu1>10.0</mu1>
        <mu2>10.0</mu2>
        <material>Gazebo/Purple</material>



    </gazebo>

    <joint name="NaroBody_3_Naro_caudal_fin_joint" type="revolute">
    	<parent link="NaroBody_3_link"/>
    	<child link="Naro_caudal_fin_link"/>
        <origin xyz="0 0 0.05357" rpy="1.5707963267948966 0 0"/>
        <limit lower="-1.0" upper="1.0" effort="5.0" velocity="1.0"/>
        <axis xyz="1 0 0"/>
	</joint>
	
    <transmission name="tran3">
        <type>transmission_interface/SimpleTransmission</type>
        <joint name="NaroBody_3_Naro_caudal_fin_joint">
            <hardwareInterface>EffortJointInterface</hardwareInterface>
        </joint>
        <actuator name="motor3">
            <hardwareInterface>EffortJointInterface</hardwareInterface>
            <mechanicalReduction>1</mechanicalReduction>
        </actuator>
    </transmission>
    

<!--3-dof Naro_pectoral_fin_right_link!-->    
    <link name="Naro_pectoral_fin_right_link_freedom1">
 	    <inertial>
            <origin xyz="0 0 0" rpy="0 0 0"/>
            <mass value="0.001" />
            <inertia ixx="3.15811533333e-05" ixy="0.0" ixz="0.0" iyy="3.00804033333e-05" iyz="0.0" izz="2.10075e-06"/>
        </inertial>
        <collision>
            <origin xyz="0 0 0" rpy="0 0 0"/>
            <geometry>
                <box size="0.001 0.001 0.001" />
            </geometry>
        </collision>
        <visual>
            <origin xyz="0 0 0" rpy="0 0 0"/>
            <geometry>
               <box size="0.001 0.001 0.001" />
            </geometry>
            <material name="purple"/>
        </visual>

	</link>
    <joint name="NaroBody_1_Naro_pectoral_fin_right_joint_1" type="revolute">
    	<parent link="base_link"/>
    	<child link="Naro_pectoral_fin_right_link_freedom1"/>
        <origin xyz="-0.04275 -0.08489 0.04478" rpy="1.5707963267948966 0 0"/>
        <limit lower="-0.4" upper="0.4" effort="0.1" velocity="0.5"/>
        <axis xyz="1 0 0"/>
	</joint>
    
    <link name="Naro_pectoral_fin_right_link_freedom2">
 	    <inertial>
            <origin xyz="0 0 0" rpy="0 0 0"/>
            <mass value="0.001" />
            <inertia ixx="3.15811533333e-05" ixy="0.0" ixz="0.0" iyy="3.00804033333e-05" iyz="0.0" izz="2.10075e-06"/>
        </inertial>
        <collision>
            <origin xyz="0 0 0" rpy="0 0 0"/>
            <geometry>
                <box size="0.001 0.001 0.001" />
            </geometry>
        </collision>
        <visual>
            <origin xyz="0 0 0" rpy="0 0 0"/>
            <geometry>
               <box size="0.001 0.001 0.001" />
            </geometry>
            <material name="purple"/>
        </visual>
	</link>
    <joint name="NaroBody_1_Naro_pectoral_fin_right_joint_2" type="revolute">
    	<parent link="Naro_pectoral_fin_right_link_freedom1"/>
    	<child link="Naro_pectoral_fin_right_link_freedom2"/>
        <origin xyz="0.002 0 0" rpy="0 0 0"/>
        <limit lower="-0.4" upper="0.4" effort="0.1" velocity="0.5"/>
        <axis xyz="0 1 0"/>
	</joint>



    <link name="Naro_pectoral_fin_right_link">
 	    <inertial>
            <origin xyz="0 0 0" rpy="0 0 0"/>
            <mass value="0.01" />
            <inertia ixx="3.15811533333e-05" ixy="0.0" ixz="0.0" iyy="3.00804033333e-05" iyz="0.0" izz="2.10075e-06"/>
        </inertial>
        <collision>
            <origin xyz="0 0 0" rpy="0 0 0"/>
            <geometry>
                <box size="0.001 0.1 0.1" />
            </geometry>
        </collision>
        <visual>
            <origin xyz="0 0 0" rpy="0 0 0"/>
            <geometry>
                <box size="0.001 0.1 0.1" />
            </geometry>
            <material name="purple"/>
        </visual>
	</link>



    <gazebo reference="Naro_pectoral_fin_right_link_freedom1">
        <kp>1000000.0</kp>
        <kd>1000000.0</kd>
        <mu1>10.0</mu1>
        <mu2>10.0</mu2>
        <material>Gazebo/Purple</material>
    </gazebo>
    <gazebo reference="Naro_pectoral_fin_right_link_freedom2">
        <kp>1000000.0</kp>
        <kd>1000000.0</kd>
        <mu1>10.0</mu1>
        <mu2>10.0</mu2>
        <material>Gazebo/Purple</material>
    </gazebo>
        <gazebo reference="Naro_pectoral_fin_right_link">
        <kp>1000000.0</kp>
        <kd>1000000.0</kd>
        <mu1>10.0</mu1>
        <mu2>10.0</mu2>
        <material>Gazebo/Purple</material>




    </gazebo>
    <joint name="NaroBody_1_Naro_pectoral_fin_right_joint_3" type="revolute">
    	<parent link="Naro_pectoral_fin_right_link_freedom2"/>
    	<child link="Naro_pectoral_fin_right_link"/>
        <origin xyz="0 0.001 0" rpy="0 0 0"/>
        <limit lower="-1.57" upper="1.57" effort="0.1" velocity="0.5"/>
        <axis xyz="0 0 1"/>
	</joint>
    <transmission name="tran4_joint1">
        <type>transmission_interface/SimpleTransmission</type>
        <joint name="NaroBody_1_Naro_pectoral_fin_right_joint_1">
            <hardwareInterface>EffortJointInterface</hardwareInterface>
        </joint>
        <actuator name="motor4_1">
            <hardwareInterface>EffortJointInterface</hardwareInterface>
            <mechanicalReduction>1</mechanicalReduction>
        </actuator>
    </transmission>
    <transmission name="tran4_joint2">
        <type>transmission_interface/SimpleTransmission</type>
        <joint name="NaroBody_1_Naro_pectoral_fin_right_joint_2">
            <hardwareInterface>EffortJointInterface</hardwareInterface>
        </joint>
        <actuator name="motor4_2">
            <hardwareInterface>EffortJointInterface</hardwareInterface>
            <mechanicalReduction>1</mechanicalReduction>
        </actuator>
    </transmission>	
    <transmission name="tran4_joint3">
        <type>transmission_interface/SimpleTransmission</type>
        <joint name="NaroBody_1_Naro_pectoral_fin_right_joint_3">
            <hardwareInterface>EffortJointInterface</hardwareInterface>
        </joint>
        <actuator name="motor4_3">
            <hardwareInterface>EffortJointInterface</hardwareInterface>
            <mechanicalReduction>1</mechanicalReduction>
        </actuator>
    </transmission>
    
<!--3-dof Naro_pectoral_fin_left_link!-->

    <link name="Naro_pectoral_fin_left_link_freedom1">
 	    <inertial>
            <origin xyz="0 0 0" rpy="0 0 0"/>
            <mass value="0.001" />
            <inertia ixx="3.15811533333e-05" ixy="0.0" ixz="0.0" iyy="3.00804033333e-05" iyz="0.0" izz="2.10075e-06"/>
        </inertial>
        <collision>
            <origin xyz="0 0 0" rpy="0 0 0"/>
            <geometry>
                <box size="0.001 0.001 0.001" />
            </geometry>
        </collision>
        <visual>
            <origin xyz="0 0 0" rpy="0 0 0"/>
            <geometry>
               <box size="0.001 0.001 0.001" />
            </geometry>
            <material name="purple"/>
        </visual>
	</link>
    <joint name="NaroBody_1_Naro_pectoral_fin_left_joint_1" type="revolute">
    	<parent link="base_link"/>
    	<child link="Naro_pectoral_fin_left_link_freedom1"/>
        <origin xyz="-0.04275 0.08489 0.04478" rpy="1.5707963267948966 0 0"/>
        <limit lower="-0.4" upper="0.4" effort="0.1" velocity="0.5"/>
        <axis xyz="1 0 0"/>
	</joint>
    
    <link name="Naro_pectoral_fin_left_link_freedom2">
 	    <inertial>
            <origin xyz="0 0 0" rpy="0 0 0"/>
            <mass value="0.001" />
            <inertia ixx="3.15811533333e-05" ixy="0.0" ixz="0.0" iyy="3.00804033333e-05" iyz="0.0" izz="2.10075e-06"/>
        </inertial>
        <collision>
            <origin xyz="0 0 0" rpy="0 0 0"/>
            <geometry>
                <box size="0.001 0.001 0.001" />
            </geometry>
        </collision>
        <visual>
            <origin xyz="0 0 0" rpy="0 0 0"/>
            <geometry>
               <box size="0.001 0.001 0.001" />
            </geometry>
            <material name="purple"/>
        </visual>
	</link>
    <joint name="NaroBody_1_Naro_pectoral_fin_left_joint_2" type="revolute">
    	<parent link="Naro_pectoral_fin_left_link_freedom1"/>
    	<child link="Naro_pectoral_fin_left_link_freedom2"/>
        <origin xyz="0.001 0 0" rpy="0 0 0"/>
        <limit lower="-0.4" upper="0.4" effort="0.1" velocity="0.5"/>
        <axis xyz="0 1 0"/>
	</joint>
    <link name="Naro_pectoral_fin_left_link">
 	    <inertial>
            <origin xyz="0 0 0" rpy="0 0 0"/>
            <mass value="0.01" />
            <inertia ixx="3.15811533333e-05" ixy="0.0" ixz="0.0" iyy="3.00804033333e-05" iyz="0.0" izz="2.10075e-06"/>
        </inertial>
        <collision>
            <origin xyz="0 0 0" rpy="0 0 0"/>
            <geometry>
                <box size="0.001 0.1 0.1" />
            </geometry>
        </collision>
        <visual>
            <origin xyz="0 0 0" rpy="0 0 0"/>
            <geometry>
                <box size="0.001 0.1 0.1" />
            </geometry>
            <material name="purple"/>
        </visual>
	</link>
  

    <gazebo reference="Naro_pectoral_fin_left_link_freedom1">
        <kp>1000000.0</kp>
        <kd>1000000.0</kd>
        <mu1>10.0</mu1>
        <mu2>10.0</mu2>
        <material>Gazebo/Purple</material>
    </gazebo>
    <gazebo reference="Naro_pectoral_fin_left_link_freedom2">
        <kp>1000000.0</kp>
        <kd>1000000.0</kd>
        <mu1>10.0</mu1>
        <mu2>10.0</mu2>
        <material>Gazebo/Purple</material>
    </gazebo>
    <gazebo reference="Naro_pectoral_fin_left_link">
        <kp>1000000.0</kp>
        <kd>1000000.0</kd>
        <mu1>10.0</mu1>
        <mu2>10.0</mu2>
        <material>Gazebo/Purple</material>



    </gazebo>

    <joint name="NaroBody_1_Naro_pectoral_fin_left_joint_3" type="revolute">
    	<parent link="Naro_pectoral_fin_left_link_freedom2"/>
    	<child link="Naro_pectoral_fin_left_link"/>
        <origin xyz="0 0 0" rpy="0 0 0"/>
        <limit lower="-1.57" upper="1.57" effort="0.1" velocity="0.5"/>
        <axis xyz="0 0 1"/>
	</joint>
	
    <transmission name="tran5_freedom1">
        <type>transmission_interface/SimpleTransmission</type>
        <joint name="NaroBody_1_Naro_pectoral_fin_left_joint_1">
            <hardwareInterface>EffortJointInterface</hardwareInterface>
        </joint>
        <actuator name="motor5_1">
            <hardwareInterface>EffortJointInterface</hardwareInterface>
            <mechanicalReduction>1</mechanicalReduction>
        </actuator>
    </transmission>
    <transmission name="tran5_freedom2">
        <type>transmission_interface/SimpleTransmission</type>
        <joint name="NaroBody_1_Naro_pectoral_fin_left_joint_2">
            <hardwareInterface>EffortJointInterface</hardwareInterface>
        </joint>
        <actuator name="motor5_2">
            <hardwareInterface>EffortJointInterface</hardwareInterface>
            <mechanicalReduction>1</mechanicalReduction>
        </actuator>
    </transmission>
    <transmission name="tran5_freedom3">
        <type>transmission_interface/SimpleTransmission</type>
        <joint name="NaroBody_1_Naro_pectoral_fin_left_joint_3">
            <hardwareInterface>EffortJointInterface</hardwareInterface>
        </joint>
        <actuator name="motor5_3">
            <hardwareInterface>EffortJointInterface</hardwareInterface>
            <mechanicalReduction>1</mechanicalReduction>
        </actuator>
    </transmission>
   
    <link name="Naro_dorsal_fin_up_link">
 	    <inertial>
            <origin xyz="0 0 0" rpy="0 0 0"/>
            <mass value="0.05" />
            <inertia ixx="3.15811533333e-05" ixy="0.0" ixz="0.0" iyy="3.00804033333e-05" iyz="0.0" izz="2.10075e-06"/>
        </inertial>
        <collision>
            <origin xyz="0 0 0" rpy="0 0 0"/>
            <geometry>
                <box size="0.006 0.0147 0.05978" />
            </geometry>
        </collision>
        <visual>
            <origin xyz="0 0 0" rpy="0 0 0"/>
            <geometry>
                <box size="0.0147 0.006 0.05978" />
            </geometry>
            <material name="purple"/>
        </visual>
	</link>
	
	<gazebo reference="Naro_dorsal_fin_up_link">
        <kp>1000000.0</kp>
        <kd>1000000.0</kd>
        <mu1>10.0</mu1>
        <mu2>10.0</mu2>
        <material>Gazebo/Purple</material>
    </gazebo>
    
    <joint name="NaroBody_1_Naro_dorsal_fin_up_joint" type="fixed">
        <parent link="NaroBody_2_link"/>
        <child link="Naro_dorsal_fin_up_link"/>
        <origin xyz="0.035795 0 0.0362" rpy="0 1.5707963267948966 0"/>
    </joint>
    
    
        <link name="Naro_dorsal_fin_down_link">
 	    <inertial>
            <origin xyz="0 0 0" rpy="0 0 0"/>
            <mass value="0.05" />
            <inertia ixx="3.15811533333e-05" ixy="0.0" ixz="0.0" iyy="3.00804033333e-05" iyz="0.0" izz="2.10075e-06"/>
        </inertial>
        <collision>
            <origin xyz="0 0 0" rpy="0 0 0"/>
            <geometry>
                <box size="0.006 0.0147 0.05978" />
            </geometry>
        </collision>
        <visual>
            <origin xyz="0 0 0" rpy="0 0 0"/>
            <geometry>
                <box size="0.0147 0.006 0.05978" />
            </geometry>
            <material name="purple"/>
        </visual>
	</link>
	
	<gazebo reference="Naro_dorsal_fin_down_link">
        <kp>1000000.0</kp>
        <kd>1000000.0</kd>
        <mu1>10.0</mu1>
        <mu2>10.0</mu2>
        <material>Gazebo/Purple</material>
    </gazebo>
    
    <joint name="NaroBody_1_Naro_dorsal_fin_down_joint" type="fixed">
        <parent link="NaroBody_2_link"/>
        <child link="Naro_dorsal_fin_down_link"/>
        <origin xyz="-0.035795 0 0.0362" rpy="0 1.5707963267948966 0"/>
    </joint>
<!-- test of lift and drag-->
    <gazebo>
    <plugin name="lifting_surface6" filename="libLiftDragPlugin.so">
        <a0>0</a0>
        <alpha_stall>1.57</alpha_stall>
        <cla>0</cla>
        <cla_stall>0</cla_stall>
        <cda>0.0</cda>
        <cda_stall>0</cda_stall>
        <cma>0.0</cma>
        <cma_stall>0.0</cma_stall>
        <area>0.01</area>
        <fluid_density>1024.1</fluid_density>
        <forward>0 1 0</forward>
        <upward>0 0 1</upward>
        <cp>0 0 0</cp>
        <link_name>base_link</link_name>
        <radial_symmetry>false</radial_symmetry>
      </plugin>
    </gazebo>

    <gazebo>
    <plugin name="lifting_surface4" filename="libLiftDragPlugin.so">
        <a0>0</a0>
        <alpha_stall>0.3368</alpha_stall>
        <cla>0</cla>
        <cla_stall>0</cla_stall>
        <cda>0.0</cda>
        <cda_stall>0</cda_stall>
        <cma>0.0</cma>
        <cma_stall>0.0</cma_stall>
        <area>0.0001</area>
        <fluid_density>1024.1</fluid_density>
        <forward>0 1 0</forward>
        <upward>0 0 1</upward>
        <cp>0 0 0</cp>
        <link_name>NaroBody_2_link</link_name>
        <radial_symmetry>false</radial_symmetry>
      </plugin>
    
    </gazebo>

    <gazebo>
      <plugin name="lifting_surface5" filename="libLiftDragPlugin.so">
        <a0>0</a0>
        <alpha_stall>1.57</alpha_stall>
        <cla>0</cla>
        <cla_stall>0</cla_stall>
        <cda>0.0</cda>
        <cda_stall>0</cda_stall>
        <cma>0.0</cma>
        <cma_stall>0.0</cma_stall>
        <area>0.0001</area>
        <fluid_density>1024.1</fluid_density>
        <forward>0 1 0</forward>
        <upward>0 0 1</upward>
        <cp>0 0 0</cp>
        <link_name>NaroBody_3_link</link_name>
        <radial_symmetry>false</radial_symmetry>
      </plugin>
    </gazebo>

    <gazebo>
      <plugin name="lifting_surface3" filename="libLiftDragPlugin.so">
            <air_density>1000</air_density>
	        <cla>0</cla>
	        <cla_stall>0</cla_stall>
	        <cda>1.2535816618911175</cda>
	        <cda_stall>1.4326647564469914</cda_stall>
	        <alpha_stall>0</alpha_stall>
	        <a0>0</a0>
            <area>0.0334265458342</area>
        <forward>1 0 0</forward>
        <upward>0 0 1</upward>
        <cp>0 0.07 0</cp>
        <link_name>Naro_caudal_fin_link</link_name>
        <radial_symmetry>false</radial_symmetry>
      </plugin>
    </gazebo>

    <gazebo>
      <plugin name="lifting_surface1" filename="libLiftDragPlugin.so">
        <a0>0</a0>
        <alpha_stall>0.3368</alpha_stall>
        <cla>5.418</cla>
        <cla_stall>-2.1419</cla_stall>
         <cda>5.2</cda>
        <cda_stall>0.2</cda_stall>
        <air_density>1000</air_density>
        <area>0.01</area>
        <forward>0 -1 0</forward>
        <upward>1 0 0</upward>
        <cp>0 0 0</cp>
        <link_name>Naro_pectoral_fin_left_link</link_name>
        <radial_symmetry>false</radial_symmetry>
      </plugin>    
    
    </gazebo>
    <gazebo>
          <plugin name="lifting_surface2" filename="libLiftDragPlugin.so">
        <a0>0</a0>
        <alpha_stall>0.3368</alpha_stall>
        <cla>5.418</cla>
        <cla_stall>-2.1419</cla_stall>
         <cda>5.2</cda>
        <cda_stall>2.2</cda_stall>
        <area>0.01</area>
        <air_density>1000</air_density>
        <cp>0 0 0</cp>
        <forward>0 -1 0</forward>
        <upward>1 0 0</upward>
        <link_name>Naro_pectoral_fin_right_link</link_name>
        <radial_symmetry>false</radial_symmetry>
      </plugin>
    </gazebo>

    <gazebo>
          <plugin name="BuoyancyPlugin1" filename="libBuoyancyPlugin.so">
            <!-- a viscous liquid -->
            <fluid_density>1024</fluid_density>
        </plugin>
    </gazebo>



</robot>